<?xml version="1.0" encoding="UTF-8"?>
<testsuite name="com.camt.plugins.RoutingTest" tests="19" skipped="0" failures="8" errors="0" timestamp="2025-07-05T10:02:51" hostname="WINFLIPPHUKRIT" time="0.329">
  <properties/>
  <testcase name="testDeleteServiceWithAppointments" classname="com.camt.plugins.RoutingTest" time="0.026">
    <failure message="java.lang.AssertionError: expected:&lt;400 Bad Request&gt; but was:&lt;200 OK&gt;" type="java.lang.AssertionError">java.lang.AssertionError: expected:&lt;400 Bad Request&gt; but was:&lt;200 OK&gt;
	at org.junit.Assert.fail(Assert.java:89)
	at org.junit.Assert.failNotEquals(Assert.java:835)
	at org.junit.Assert.assertEquals(Assert.java:120)
	at kotlin.test.junit.JUnitAsserter.assertEquals(JUnitSupport.kt:32)
	at kotlin.test.AssertionsKt__AssertionsKt.assertEquals(Assertions.kt:63)
	at kotlin.test.AssertionsKt.assertEquals(Unknown Source)
	at kotlin.test.AssertionsKt__AssertionsKt.assertEquals$default(Assertions.kt:62)
	at kotlin.test.AssertionsKt.assertEquals$default(Unknown Source)
	at com.camt.plugins.RoutingTest$testDeleteServiceWithAppointments$1.invokeSuspend(RoutingTest.kt:353)
	at _COROUTINE._BOUNDARY._(CoroutineDebugging.kt:42)
	at io.ktor.server.testing.TestApplicationKt.runTestApplication(TestApplication.kt:528)
	at io.ktor.server.testing.TestApplicationKt$testApplication$1.invokeSuspend(TestApplication.kt:511)
	at io.ktor.test.dispatcher.TestCommonKt$runTestWithRealTime$1.invokeSuspend(TestCommon.kt:40)
	at kotlinx.coroutines.test.TestBuildersKt__TestBuildersKt$runTest$2$1$1.invokeSuspend(TestBuilders.kt:317)
Caused by: java.lang.AssertionError: expected:&lt;400 Bad Request&gt; but was:&lt;200 OK&gt;
	at org.junit.Assert.fail(Assert.java:89)
	at org.junit.Assert.failNotEquals(Assert.java:835)
	at org.junit.Assert.assertEquals(Assert.java:120)
	at kotlin.test.junit.JUnitAsserter.assertEquals(JUnitSupport.kt:32)
	at kotlin.test.AssertionsKt__AssertionsKt.assertEquals(Assertions.kt:63)
	at kotlin.test.AssertionsKt.assertEquals(Unknown Source)
	at kotlin.test.AssertionsKt__AssertionsKt.assertEquals$default(Assertions.kt:62)
	at kotlin.test.AssertionsKt.assertEquals$default(Unknown Source)
	at com.camt.plugins.RoutingTest$testDeleteServiceWithAppointments$1.invokeSuspend(RoutingTest.kt:353)
	at kotlin.coroutines.jvm.internal.BaseContinuationImpl.resumeWith(ContinuationImpl.kt:33)
	at kotlinx.coroutines.DispatchedTask.run(DispatchedTask.kt:100)
	at kotlinx.coroutines.internal.LimitedDispatcher$Worker.run(LimitedDispatcher.kt:124)
	at kotlinx.coroutines.scheduling.TaskImpl.run(Tasks.kt:89)
	at kotlinx.coroutines.scheduling.CoroutineScheduler.runSafely(CoroutineScheduler.kt:586)
	at kotlinx.coroutines.scheduling.CoroutineScheduler$Worker.executeTask(CoroutineScheduler.kt:829)
	at kotlinx.coroutines.scheduling.CoroutineScheduler$Worker.runWorker(CoroutineScheduler.kt:717)
	at kotlinx.coroutines.scheduling.CoroutineScheduler$Worker.run(CoroutineScheduler.kt:704)
</failure>
  </testcase>
  <testcase name="testGetAppointmentByIdNotFound" classname="com.camt.plugins.RoutingTest" time="0.021"/>
  <testcase name="testUpdateService" classname="com.camt.plugins.RoutingTest" time="0.016"/>
  <testcase name="testCreateAppointmentWithInvalidService" classname="com.camt.plugins.RoutingTest" time="0.016"/>
  <testcase name="testGetServiceByIdNotFound" classname="com.camt.plugins.RoutingTest" time="0.012"/>
  <testcase name="testGetAllServicesEmpty" classname="com.camt.plugins.RoutingTest" time="0.012">
    <failure message="java.lang.AssertionError: Expected value to be true." type="java.lang.AssertionError">java.lang.AssertionError: Expected value to be true.
	at org.junit.Assert.fail(Assert.java:89)
	at kotlin.test.junit.JUnitAsserter.fail(JUnitSupport.kt:56)
	at kotlin.test.Asserter$DefaultImpls.assertTrue(Assertions.kt:694)
	at kotlin.test.junit.JUnitAsserter.assertTrue(JUnitSupport.kt:30)
	at kotlin.test.Asserter$DefaultImpls.assertTrue(Assertions.kt:704)
	at kotlin.test.junit.JUnitAsserter.assertTrue(JUnitSupport.kt:30)
	at kotlin.test.AssertionsKt__AssertionsKt.assertTrue(Assertions.kt:44)
	at kotlin.test.AssertionsKt.assertTrue(Unknown Source)
	at kotlin.test.AssertionsKt__AssertionsKt.assertTrue$default(Assertions.kt:42)
	at kotlin.test.AssertionsKt.assertTrue$default(Unknown Source)
	at com.camt.plugins.RoutingTest$testGetAllServicesEmpty$1.invokeSuspend(RoutingTest.kt:51)
	at _COROUTINE._BOUNDARY._(CoroutineDebugging.kt:42)
	at io.ktor.server.testing.TestApplicationKt.runTestApplication(TestApplication.kt:528)
	at io.ktor.server.testing.TestApplicationKt$testApplication$1.invokeSuspend(TestApplication.kt:511)
	at io.ktor.test.dispatcher.TestCommonKt$runTestWithRealTime$1.invokeSuspend(TestCommon.kt:40)
	at kotlinx.coroutines.test.TestBuildersKt__TestBuildersKt$runTest$2$1$1.invokeSuspend(TestBuilders.kt:317)
Caused by: java.lang.AssertionError: Expected value to be true.
	at org.junit.Assert.fail(Assert.java:89)
	at kotlin.test.junit.JUnitAsserter.fail(JUnitSupport.kt:56)
	at kotlin.test.Asserter$DefaultImpls.assertTrue(Assertions.kt:694)
	at kotlin.test.junit.JUnitAsserter.assertTrue(JUnitSupport.kt:30)
	at kotlin.test.Asserter$DefaultImpls.assertTrue(Assertions.kt:704)
	at kotlin.test.junit.JUnitAsserter.assertTrue(JUnitSupport.kt:30)
	at kotlin.test.AssertionsKt__AssertionsKt.assertTrue(Assertions.kt:44)
	at kotlin.test.AssertionsKt.assertTrue(Unknown Source)
	at kotlin.test.AssertionsKt__AssertionsKt.assertTrue$default(Assertions.kt:42)
	at kotlin.test.AssertionsKt.assertTrue$default(Unknown Source)
	at com.camt.plugins.RoutingTest$testGetAllServicesEmpty$1.invokeSuspend(RoutingTest.kt:51)
	at kotlin.coroutines.jvm.internal.BaseContinuationImpl.resumeWith(ContinuationImpl.kt:33)
	at kotlinx.coroutines.DispatchedTask.run(DispatchedTask.kt:100)
	at kotlinx.coroutines.internal.LimitedDispatcher$Worker.run(LimitedDispatcher.kt:124)
	at kotlinx.coroutines.scheduling.TaskImpl.run(Tasks.kt:89)
	at kotlinx.coroutines.scheduling.CoroutineScheduler.runSafely(CoroutineScheduler.kt:586)
	at kotlinx.coroutines.scheduling.CoroutineScheduler$Worker.executeTask(CoroutineScheduler.kt:829)
	at kotlinx.coroutines.scheduling.CoroutineScheduler$Worker.runWorker(CoroutineScheduler.kt:717)
	at kotlinx.coroutines.scheduling.CoroutineScheduler$Worker.run(CoroutineScheduler.kt:704)
</failure>
  </testcase>
  <testcase name="testDeleteService" classname="com.camt.plugins.RoutingTest" time="0.017"/>
  <testcase name="testUpdateAppointment" classname="com.camt.plugins.RoutingTest" time="0.015">
    <failure message="java.lang.NullPointerException" type="java.lang.NullPointerException">java.lang.NullPointerException
	at com.camt.plugins.RoutingTest$testUpdateAppointment$1.invokeSuspend(RoutingTest.kt:659)
	at _COROUTINE._BOUNDARY._(CoroutineDebugging.kt:42)
	at io.ktor.server.testing.TestApplicationKt.runTestApplication(TestApplication.kt:528)
	at io.ktor.server.testing.TestApplicationKt$testApplication$1.invokeSuspend(TestApplication.kt:511)
	at io.ktor.test.dispatcher.TestCommonKt$runTestWithRealTime$1.invokeSuspend(TestCommon.kt:40)
	at kotlinx.coroutines.test.TestBuildersKt__TestBuildersKt$runTest$2$1$1.invokeSuspend(TestBuilders.kt:317)
Caused by: java.lang.NullPointerException
	at com.camt.plugins.RoutingTest$testUpdateAppointment$1.invokeSuspend(RoutingTest.kt:659)
	at kotlin.coroutines.jvm.internal.BaseContinuationImpl.resumeWith(ContinuationImpl.kt:33)
	at kotlinx.coroutines.DispatchedTask.run(DispatchedTask.kt:100)
	at kotlinx.coroutines.internal.LimitedDispatcher$Worker.run(LimitedDispatcher.kt:124)
	at kotlinx.coroutines.scheduling.TaskImpl.run(Tasks.kt:89)
	at kotlinx.coroutines.scheduling.CoroutineScheduler.runSafely(CoroutineScheduler.kt:586)
	at kotlinx.coroutines.scheduling.CoroutineScheduler$Worker.executeTask(CoroutineScheduler.kt:829)
	at kotlinx.coroutines.scheduling.CoroutineScheduler$Worker.runWorker(CoroutineScheduler.kt:717)
	at kotlinx.coroutines.scheduling.CoroutineScheduler$Worker.run(CoroutineScheduler.kt:704)
</failure>
  </testcase>
  <testcase name="testUpdateServiceNotFound" classname="com.camt.plugins.RoutingTest" time="0.025"/>
  <testcase name="testGetServiceByIdInvalidId" classname="com.camt.plugins.RoutingTest" time="0.011"/>
  <testcase name="testRootRoute" classname="com.camt.plugins.RoutingTest" time="0.015"/>
  <testcase name="testCreateAppointmentDoubleBooking" classname="com.camt.plugins.RoutingTest" time="0.019">
    <failure message="java.lang.AssertionError: expected:&lt;201 Created&gt; but was:&lt;409 Conflict&gt;" type="java.lang.AssertionError">java.lang.AssertionError: expected:&lt;201 Created&gt; but was:&lt;409 Conflict&gt;
	at org.junit.Assert.fail(Assert.java:89)
	at org.junit.Assert.failNotEquals(Assert.java:835)
	at org.junit.Assert.assertEquals(Assert.java:120)
	at kotlin.test.junit.JUnitAsserter.assertEquals(JUnitSupport.kt:32)
	at kotlin.test.AssertionsKt__AssertionsKt.assertEquals(Assertions.kt:63)
	at kotlin.test.AssertionsKt.assertEquals(Unknown Source)
	at kotlin.test.AssertionsKt__AssertionsKt.assertEquals$default(Assertions.kt:62)
	at kotlin.test.AssertionsKt.assertEquals$default(Unknown Source)
	at com.camt.plugins.RoutingTest$testCreateAppointmentDoubleBooking$1.invokeSuspend(RoutingTest.kt:516)
	at _COROUTINE._BOUNDARY._(CoroutineDebugging.kt:42)
	at io.ktor.server.testing.TestApplicationKt.runTestApplication(TestApplication.kt:528)
	at io.ktor.server.testing.TestApplicationKt$testApplication$1.invokeSuspend(TestApplication.kt:511)
	at io.ktor.test.dispatcher.TestCommonKt$runTestWithRealTime$1.invokeSuspend(TestCommon.kt:40)
	at kotlinx.coroutines.test.TestBuildersKt__TestBuildersKt$runTest$2$1$1.invokeSuspend(TestBuilders.kt:317)
Caused by: java.lang.AssertionError: expected:&lt;201 Created&gt; but was:&lt;409 Conflict&gt;
	at org.junit.Assert.fail(Assert.java:89)
	at org.junit.Assert.failNotEquals(Assert.java:835)
	at org.junit.Assert.assertEquals(Assert.java:120)
	at kotlin.test.junit.JUnitAsserter.assertEquals(JUnitSupport.kt:32)
	at kotlin.test.AssertionsKt__AssertionsKt.assertEquals(Assertions.kt:63)
	at kotlin.test.AssertionsKt.assertEquals(Unknown Source)
	at kotlin.test.AssertionsKt__AssertionsKt.assertEquals$default(Assertions.kt:62)
	at kotlin.test.AssertionsKt.assertEquals$default(Unknown Source)
	at com.camt.plugins.RoutingTest$testCreateAppointmentDoubleBooking$1.invokeSuspend(RoutingTest.kt:516)
	at kotlin.coroutines.jvm.internal.BaseContinuationImpl.resumeWith(ContinuationImpl.kt:33)
	at kotlinx.coroutines.DispatchedTask.run(DispatchedTask.kt:100)
	at kotlinx.coroutines.internal.LimitedDispatcher$Worker.run(LimitedDispatcher.kt:124)
	at kotlinx.coroutines.scheduling.TaskImpl.run(Tasks.kt:89)
	at kotlinx.coroutines.scheduling.CoroutineScheduler.runSafely(CoroutineScheduler.kt:586)
	at kotlinx.coroutines.scheduling.CoroutineScheduler$Worker.executeTask(CoroutineScheduler.kt:829)
	at kotlinx.coroutines.scheduling.CoroutineScheduler$Worker.runWorker(CoroutineScheduler.kt:717)
	at kotlinx.coroutines.scheduling.CoroutineScheduler$Worker.run(CoroutineScheduler.kt:704)
</failure>
  </testcase>
  <testcase name="testGetAllAppointmentsEmpty" classname="com.camt.plugins.RoutingTest" time="0.017">
    <failure message="java.lang.AssertionError: Expected value to be true." type="java.lang.AssertionError">java.lang.AssertionError: Expected value to be true.
	at org.junit.Assert.fail(Assert.java:89)
	at kotlin.test.junit.JUnitAsserter.fail(JUnitSupport.kt:56)
	at kotlin.test.Asserter$DefaultImpls.assertTrue(Assertions.kt:694)
	at kotlin.test.junit.JUnitAsserter.assertTrue(JUnitSupport.kt:30)
	at kotlin.test.Asserter$DefaultImpls.assertTrue(Assertions.kt:704)
	at kotlin.test.junit.JUnitAsserter.assertTrue(JUnitSupport.kt:30)
	at kotlin.test.AssertionsKt__AssertionsKt.assertTrue(Assertions.kt:44)
	at kotlin.test.AssertionsKt.assertTrue(Unknown Source)
	at kotlin.test.AssertionsKt__AssertionsKt.assertTrue$default(Assertions.kt:42)
	at kotlin.test.AssertionsKt.assertTrue$default(Unknown Source)
	at com.camt.plugins.RoutingTest$testGetAllAppointmentsEmpty$1.invokeSuspend(RoutingTest.kt:381)
	at _COROUTINE._BOUNDARY._(CoroutineDebugging.kt:42)
	at io.ktor.server.testing.TestApplicationKt.runTestApplication(TestApplication.kt:528)
	at io.ktor.server.testing.TestApplicationKt$testApplication$1.invokeSuspend(TestApplication.kt:511)
	at io.ktor.test.dispatcher.TestCommonKt$runTestWithRealTime$1.invokeSuspend(TestCommon.kt:40)
	at kotlinx.coroutines.test.TestBuildersKt__TestBuildersKt$runTest$2$1$1.invokeSuspend(TestBuilders.kt:317)
Caused by: java.lang.AssertionError: Expected value to be true.
	at org.junit.Assert.fail(Assert.java:89)
	at kotlin.test.junit.JUnitAsserter.fail(JUnitSupport.kt:56)
	at kotlin.test.Asserter$DefaultImpls.assertTrue(Assertions.kt:694)
	at kotlin.test.junit.JUnitAsserter.assertTrue(JUnitSupport.kt:30)
	at kotlin.test.Asserter$DefaultImpls.assertTrue(Assertions.kt:704)
	at kotlin.test.junit.JUnitAsserter.assertTrue(JUnitSupport.kt:30)
	at kotlin.test.AssertionsKt__AssertionsKt.assertTrue(Assertions.kt:44)
	at kotlin.test.AssertionsKt.assertTrue(Unknown Source)
	at kotlin.test.AssertionsKt__AssertionsKt.assertTrue$default(Assertions.kt:42)
	at kotlin.test.AssertionsKt.assertTrue$default(Unknown Source)
	at com.camt.plugins.RoutingTest$testGetAllAppointmentsEmpty$1.invokeSuspend(RoutingTest.kt:381)
	at kotlin.coroutines.jvm.internal.BaseContinuationImpl.resumeWith(ContinuationImpl.kt:33)
	at kotlinx.coroutines.DispatchedTask.run(DispatchedTask.kt:100)
	at kotlinx.coroutines.internal.LimitedDispatcher$Worker.run(LimitedDispatcher.kt:124)
	at kotlinx.coroutines.scheduling.TaskImpl.run(Tasks.kt:89)
	at kotlinx.coroutines.scheduling.CoroutineScheduler.runSafely(CoroutineScheduler.kt:586)
	at kotlinx.coroutines.scheduling.CoroutineScheduler$Worker.executeTask(CoroutineScheduler.kt:829)
	at kotlinx.coroutines.scheduling.CoroutineScheduler$Worker.runWorker(CoroutineScheduler.kt:717)
	at kotlinx.coroutines.scheduling.CoroutineScheduler$Worker.run(CoroutineScheduler.kt:704)
</failure>
  </testcase>
  <testcase name="testGetServiceById" classname="com.camt.plugins.RoutingTest" time="0.019"/>
  <testcase name="testGetAppointmentById" classname="com.camt.plugins.RoutingTest" time="0.02">
    <failure message="java.lang.NullPointerException" type="java.lang.NullPointerException">java.lang.NullPointerException
	at com.camt.plugins.RoutingTest$testGetAppointmentById$1.invokeSuspend(RoutingTest.kt:580)
	at _COROUTINE._BOUNDARY._(CoroutineDebugging.kt:42)
	at io.ktor.server.testing.TestApplicationKt.runTestApplication(TestApplication.kt:528)
	at io.ktor.server.testing.TestApplicationKt$testApplication$1.invokeSuspend(TestApplication.kt:511)
	at io.ktor.test.dispatcher.TestCommonKt$runTestWithRealTime$1.invokeSuspend(TestCommon.kt:40)
	at kotlinx.coroutines.test.TestBuildersKt__TestBuildersKt$runTest$2$1$1.invokeSuspend(TestBuilders.kt:317)
Caused by: java.lang.NullPointerException
	at com.camt.plugins.RoutingTest$testGetAppointmentById$1.invokeSuspend(RoutingTest.kt:580)
	at kotlin.coroutines.jvm.internal.BaseContinuationImpl.resumeWith(ContinuationImpl.kt:33)
	at kotlinx.coroutines.DispatchedTask.run(DispatchedTask.kt:100)
	at kotlinx.coroutines.internal.LimitedDispatcher$Worker.run(LimitedDispatcher.kt:124)
	at kotlinx.coroutines.scheduling.TaskImpl.run(Tasks.kt:89)
	at kotlinx.coroutines.scheduling.CoroutineScheduler.runSafely(CoroutineScheduler.kt:586)
	at kotlinx.coroutines.scheduling.CoroutineScheduler$Worker.executeTask(CoroutineScheduler.kt:829)
	at kotlinx.coroutines.scheduling.CoroutineScheduler$Worker.runWorker(CoroutineScheduler.kt:717)
	at kotlinx.coroutines.scheduling.CoroutineScheduler$Worker.run(CoroutineScheduler.kt:704)
</failure>
  </testcase>
  <testcase name="testDeleteAppointment" classname="com.camt.plugins.RoutingTest" time="0.017">
    <failure message="java.lang.NullPointerException" type="java.lang.NullPointerException">java.lang.NullPointerException
	at com.camt.plugins.RoutingTest$testDeleteAppointment$1.invokeSuspend(RoutingTest.kt:725)
	at _COROUTINE._BOUNDARY._(CoroutineDebugging.kt:42)
	at io.ktor.server.testing.TestApplicationKt.runTestApplication(TestApplication.kt:528)
	at io.ktor.server.testing.TestApplicationKt$testApplication$1.invokeSuspend(TestApplication.kt:511)
	at io.ktor.test.dispatcher.TestCommonKt$runTestWithRealTime$1.invokeSuspend(TestCommon.kt:40)
	at kotlinx.coroutines.test.TestBuildersKt__TestBuildersKt$runTest$2$1$1.invokeSuspend(TestBuilders.kt:317)
Caused by: java.lang.NullPointerException
	at com.camt.plugins.RoutingTest$testDeleteAppointment$1.invokeSuspend(RoutingTest.kt:725)
	at kotlin.coroutines.jvm.internal.BaseContinuationImpl.resumeWith(ContinuationImpl.kt:33)
	at kotlinx.coroutines.DispatchedTask.run(DispatchedTask.kt:100)
	at kotlinx.coroutines.internal.LimitedDispatcher$Worker.run(LimitedDispatcher.kt:124)
	at kotlinx.coroutines.scheduling.TaskImpl.run(Tasks.kt:89)
	at kotlinx.coroutines.scheduling.CoroutineScheduler.runSafely(CoroutineScheduler.kt:586)
	at kotlinx.coroutines.scheduling.CoroutineScheduler$Worker.executeTask(CoroutineScheduler.kt:829)
	at kotlinx.coroutines.scheduling.CoroutineScheduler$Worker.runWorker(CoroutineScheduler.kt:717)
	at kotlinx.coroutines.scheduling.CoroutineScheduler$Worker.run(CoroutineScheduler.kt:704)
</failure>
  </testcase>
  <testcase name="testDeleteAppointmentNotFound" classname="com.camt.plugins.RoutingTest" time="0.015"/>
  <testcase name="testCreateAppointment" classname="com.camt.plugins.RoutingTest" time="0.018">
    <failure message="java.lang.AssertionError: expected:&lt;201 Created&gt; but was:&lt;409 Conflict&gt;" type="java.lang.AssertionError">java.lang.AssertionError: expected:&lt;201 Created&gt; but was:&lt;409 Conflict&gt;
	at org.junit.Assert.fail(Assert.java:89)
	at org.junit.Assert.failNotEquals(Assert.java:835)
	at org.junit.Assert.assertEquals(Assert.java:120)
	at kotlin.test.junit.JUnitAsserter.assertEquals(JUnitSupport.kt:32)
	at kotlin.test.AssertionsKt__AssertionsKt.assertEquals(Assertions.kt:63)
	at kotlin.test.AssertionsKt.assertEquals(Unknown Source)
	at kotlin.test.AssertionsKt__AssertionsKt.assertEquals$default(Assertions.kt:62)
	at kotlin.test.AssertionsKt.assertEquals$default(Unknown Source)
	at com.camt.plugins.RoutingTest$testCreateAppointment$1.invokeSuspend(RoutingTest.kt:427)
	at _COROUTINE._BOUNDARY._(CoroutineDebugging.kt:42)
	at io.ktor.server.testing.TestApplicationKt.runTestApplication(TestApplication.kt:528)
	at io.ktor.server.testing.TestApplicationKt$testApplication$1.invokeSuspend(TestApplication.kt:511)
	at io.ktor.test.dispatcher.TestCommonKt$runTestWithRealTime$1.invokeSuspend(TestCommon.kt:40)
	at kotlinx.coroutines.test.TestBuildersKt__TestBuildersKt$runTest$2$1$1.invokeSuspend(TestBuilders.kt:317)
Caused by: java.lang.AssertionError: expected:&lt;201 Created&gt; but was:&lt;409 Conflict&gt;
	at org.junit.Assert.fail(Assert.java:89)
	at org.junit.Assert.failNotEquals(Assert.java:835)
	at org.junit.Assert.assertEquals(Assert.java:120)
	at kotlin.test.junit.JUnitAsserter.assertEquals(JUnitSupport.kt:32)
	at kotlin.test.AssertionsKt__AssertionsKt.assertEquals(Assertions.kt:63)
	at kotlin.test.AssertionsKt.assertEquals(Unknown Source)
	at kotlin.test.AssertionsKt__AssertionsKt.assertEquals$default(Assertions.kt:62)
	at kotlin.test.AssertionsKt.assertEquals$default(Unknown Source)
	at com.camt.plugins.RoutingTest$testCreateAppointment$1.invokeSuspend(RoutingTest.kt:427)
	at kotlin.coroutines.jvm.internal.BaseContinuationImpl.resumeWith(ContinuationImpl.kt:33)
	at kotlinx.coroutines.DispatchedTask.run(DispatchedTask.kt:100)
	at kotlinx.coroutines.internal.LimitedDispatcher$Worker.run(LimitedDispatcher.kt:124)
	at kotlinx.coroutines.scheduling.TaskImpl.run(Tasks.kt:89)
	at kotlinx.coroutines.scheduling.CoroutineScheduler.runSafely(CoroutineScheduler.kt:586)
	at kotlinx.coroutines.scheduling.CoroutineScheduler$Worker.executeTask(CoroutineScheduler.kt:829)
	at kotlinx.coroutines.scheduling.CoroutineScheduler$Worker.runWorker(CoroutineScheduler.kt:717)
	at kotlinx.coroutines.scheduling.CoroutineScheduler$Worker.run(CoroutineScheduler.kt:704)
</failure>
  </testcase>
  <testcase name="testCreateService" classname="com.camt.plugins.RoutingTest" time="0.015"/>
  <system-out><![CDATA[]]></system-out>
  <system-err><![CDATA[]]></system-err>
</testsuite>
